Traceback (most recent call last):
  File "/srv/conda/envs/notebook/lib/python3.9/site-packages/jupyter_cache/executors/utils.py", line 51, in single_nb_execution
    executenb(
  File "/srv/conda/envs/notebook/lib/python3.9/site-packages/nbclient/client.py", line 1093, in execute
    return NotebookClient(nb=nb, resources=resources, km=km, **kwargs).execute()
  File "/srv/conda/envs/notebook/lib/python3.9/site-packages/nbclient/util.py", line 84, in wrapped
    return just_run(coro(*args, **kwargs))
  File "/srv/conda/envs/notebook/lib/python3.9/site-packages/nbclient/util.py", line 62, in just_run
    return loop.run_until_complete(coro)
  File "/srv/conda/envs/notebook/lib/python3.9/asyncio/base_events.py", line 642, in run_until_complete
    return future.result()
  File "/srv/conda/envs/notebook/lib/python3.9/site-packages/nbclient/client.py", line 559, in async_execute
    await self.async_execute_cell(
  File "/srv/conda/envs/notebook/lib/python3.9/site-packages/nbclient/client.py", line 854, in async_execute_cell
    self._check_raise_for_error(cell, exec_reply)
  File "/srv/conda/envs/notebook/lib/python3.9/site-packages/nbclient/client.py", line 756, in _check_raise_for_error
    raise CellExecutionError.from_cell_and_msg(cell, exec_reply_content)
nbclient.exceptions.CellExecutionError: An error occurred while executing the following cell:
------------------
# Extract the parameters for the desired event:
event = events[eventname]
fn_H1 = 'data/'+event['fn_H1']              # File name for H1 data
fn_L1 = 'data/'+event['fn_L1']              # File name for L1 data
fn_template = 'data/'+event['fn_template']  # File name for template waveform
fs = event['fs']                    # Set sampling rate
tevent = event['tevent']            # Set approximate event GPS time
fband = event['fband']              # frequency band for bandpassing signal
print("Reading in parameters for event " + event["name"])
print(event)
------------------

[0;31m---------------------------------------------------------------------------[0m
[0;31mNameError[0m                                 Traceback (most recent call last)
[0;32m<ipython-input-4-ebb27d78a52d>[0m in [0;36m<module>[0;34m()[0m
[1;32m      1[0m [0;31m# Extract the parameters for the desired event:[0m[0;34m[0m[0;34m[0m[0m
[0;32m----> 2[0;31m [0mevent[0m [0;34m=[0m [0mevents[0m[0;34m[[0m[0meventname[0m[0;34m][0m[0;34m[0m[0m
[0m[1;32m      3[0m [0mfn_H1[0m [0;34m=[0m [0;34m'data/'[0m[0;34m+[0m[0mevent[0m[0;34m[[0m[0;34m'fn_H1'[0m[0;34m][0m              [0;31m# File name for H1 data[0m[0;34m[0m[0m
[1;32m      4[0m [0mfn_L1[0m [0;34m=[0m [0;34m'data/'[0m[0;34m+[0m[0mevent[0m[0;34m[[0m[0;34m'fn_L1'[0m[0;34m][0m              [0;31m# File name for L1 data[0m[0;34m[0m[0m
[1;32m      5[0m [0mfn_template[0m [0;34m=[0m [0;34m'data/'[0m[0;34m+[0m[0mevent[0m[0;34m[[0m[0;34m'fn_template'[0m[0;34m][0m  [0;31m# File name for template waveform[0m[0;34m[0m[0m

[0;31mNameError[0m: name 'events' is not defined
NameError: name 'events' is not defined

